File: data/raw/LCE_properties/LCE_DSC.txt
Sample size	8.1	mg
Temperature (°C)	Heat Flow (mW)
-39.885	-0.1445219
-39.8999	-0.1480194
-39.91141	-0.1505024
-39.91989	-0.1527289
-39.92682	-0.1546283
-39.93246	-0.1560693
-39.93508	-0.1579381
-39.93906	-0.1589771
-39.94214	-0.1598522
-39.94374	-0.1604526
-39.9468	-0.1611978
-39.94764	-0.1621822
-39.94848	-0.1626225
-39.95058	-0.1627254
-39.95158	-0.1631041
-39.95305	-0.1634029
-39.95331	-0.1640215
-39.95477	-0.1645351
-39.95561	-0.1646711
-39.95652	-0.1650898
-39.95669	-0.1656386
-39.95854	-0.1660266
-39.95856	-0.166397
-39.959	-0.1669155
-39.95911	-0.167193
-39.9596	-0.1677654
-39.96	-0.1676321
-39.96044	-0.1679495
-39.96133	-0.1678423
-39.96216	-0.1678493
-39.96226	-0.1682419
-39.9612	-0.1688051
-39.95237	-0.1571824
-39.81312	-0.4353672
-39.53246	-0.6151242
-39.16768	-0.6905188
-38.74972	-0.7151059
-38.31355	-0.7251165
-37.86572	-0.7320106
-37.4003	-0.7374297
-36.92956	-0.7419669
-36.46301	-0.7464682
-35.99496	-0.751113
-35.51756	-0.75575
-35.04628	-0.7604594
-34.57563	-0.766311
-34.09472	-0.7725874
-33.61328	-0.7786113
-33.14966	-0.7844343
-32.66762	-0.7910828
-32.1872	-0.7973538
-31.71274	-0.8038728
-31.24002	-0.8101485
-30.75724	-0.8166816
-30.27542	-0.8224549
-29.81063	-0.8281621
-29.32864	-0.8338672
-28.84678	-0.8396789
-28.37232	-0.8455657
-27.8993	-0.8511061
-27.41659	-0.8575984
-26.94342	-0.8646088
-26.46892	-0.8716278
-25.98706	-0.8791695
-25.506	-0.8874757
-25.03164	-0.8960224
-24.5576	-0.9053702
-24.07512	-0.9156981
-23.60213	-0.9259284
-23.12805	-0.9368736
-22.64648	-0.9485109
-22.16387	-0.9594819
-21.69803	-0.9697397
-21.21611	-0.9797832
-20.73383	-0.989267
-20.26006	-0.997414
-19.78523	-1.00393
-19.30333	-1.009366
-18.82127	-1.013896
-18.3547	-1.016281
-17.87258	-1.018142
-17.3897	-1.019488
-16.91495	-1.020092
-16.44086	-1.020248
-15.95826	-1.020006
-15.48394	-1.020432
-15.00984	-1.020759
-14.52676	-1.021064
-14.04425	-1.021393
-13.56978	-1.021516
-13.09601	-1.021675
-12.61254	-1.023017
-12.13814	-1.023459
-11.66384	-1.024136
-11.18104	-1.024556
-10.69953	-1.024767
-10.23304	-1.025756
-9.750656	-1.026566
-9.267569	-1.027518
-8.793612	-1.028482
-8.318681	-1.029205
-7.836952	-1.029739
-7.353934	-1.031009
-6.88687	-1.032032
-6.40467	-1.032634
-5.921766	-1.033847
-5.4473	-1.034546
-4.97307	-1.035389
-4.490088	-1.037018
-4.014568	-1.038807
-3.539666	-1.040235
-3.057925	-1.041634
-2.574792	-1.042951
-2.100318	-1.045345
-1.625491	-1.047331
-1.142012	-1.049802
-0.6680337	-1.052064
-0.1932748	-1.054141
0.2891541	-1.055614
0.7725934	-1.057792
1.238624	-1.059994
1.721668	-1.062289
2.203482	-1.063822
2.677838	-1.06584
3.152525	-1.068008
3.634817	-1.070238
4.117834	-1.072539
4.584024	-1.074804
5.067168	-1.077726
5.549824	-1.079803
6.024166	-1.082162
6.499459	-1.084984
6.981671	-1.087559
7.456689	-1.090314
7.930634	-1.09324
8.412941	-1.096915
8.894914	-1.101748
9.370181	-1.107819
9.844219	-1.115151
10.32643	-1.124498
10.80002	-1.134319
11.2751	-1.139594
11.75862	-1.136746
12.24246	-1.130168
12.70792	-1.124834
13.19116	-1.121715
13.67407	-1.119699
14.1483	-1.11882
14.6227	-1.119584
15.10587	-1.120296
15.58794	-1.120918
16.05502	-1.122852
16.53794	-1.124672
17.02003	-1.125683
17.49444	-1.126716
17.96899	-1.128281
18.45126	-1.129972
18.92563	-1.131744
19.40085	-1.133966
19.88325	-1.1358
20.36592	-1.137517
20.841	-1.139275
21.3158	-1.140987
21.79856	-1.142584
22.27301	-1.143753
22.74794	-1.145515
23.23013	-1.146763
23.71287	-1.148456
24.18009	-1.150628
24.66219	-1.15232
25.1447	-1.15373
25.61925	-1.155758
26.09378	-1.157418
26.57666	-1.159316
27.05856	-1.160179
27.52534	-1.162143
28.00867	-1.164704
28.49202	-1.166301
28.96652	-1.167952
29.44113	-1.168799
29.92292	-1.169691
30.39759	-1.171455
30.87201	-1.173427
31.35443	-1.174532
31.83814	-1.176397
32.31218	-1.177644
32.78692	-1.179034
33.2687	-1.17978
33.7431	-1.181043
34.2197	-1.183798
34.70312	-1.185135
35.18562	-1.185876
35.65228	-1.187001
36.13352	-1.187089
36.61631	-1.188124
37.09026	-1.189116
37.56514	-1.190588
38.04735	-1.192135
38.5313	-1.194511
38.99712	-1.195252
39.48074	-1.197269
39.96309	-1.197962
40.43669	-1.19839
40.91146	-1.199522
41.39477	-1.201097
41.86933	-1.202365
42.34434	-1.204
42.82652	-1.204853
43.3093	-1.206119
43.78453	-1.207651
44.25972	-1.209443
44.74154	-1.210095
45.21616	-1.211024
45.69096	-1.212723
46.17403	-1.214065
46.65705	-1.214882
47.12344	-1.216083
47.60575	-1.217009
48.08816	-1.218911
48.56236	-1.220223
49.0382	-1.221814
49.51858	-1.222039
50.00147	-1.22296
50.46964	-1.22614
50.95371	-1.228006
51.43606	-1.228776
51.90902	-1.228761
52.38375	-1.230296
52.86657	-1.232607
53.34194	-1.234159
53.81493	-1.234366
54.2985	-1.23623
54.78124	-1.237596
55.25567	-1.239122
55.72985	-1.239989
56.21287	-1.241041
56.6869	-1.242772
57.16032	-1.243929
57.64528	-1.246819
58.12906	-1.249026
58.5952	-1.249728
59.07816	-1.250265
59.55982	-1.250668
60.03462	-1.252316
60.50832	-1.253332
60.98945	-1.253967
61.47441	-1.257675
61.94134	-1.259905
62.42462	-1.261166
62.90571	-1.261412
63.38049	-1.262781
63.8552	-1.264495
64.3367	-1.265412
64.81192	-1.268122
65.28669	-1.270213
65.76949	-1.271811
66.25293	-1.272796
66.72712	-1.274637
67.20118	-1.27606
67.68444	-1.277483
68.15958	-1.279604
68.63394	-1.281592
69.11506	-1.282414
69.59885	-1.284719
70.06522	-1.287072
70.54786	-1.288569
71.03088	-1.290675
71.50642	-1.293062
71.98044	-1.294767
72.46276	-1.296304
72.94566	-1.297938
73.41062	-1.299609
73.8937	-1.302852
74.37776	-1.305841
74.85132	-1.308148
75.32606	-1.310491
75.8086	-1.31282
76.28329	-1.31591
76.75621	-1.317466
77.2405	-1.322153
77.72368	-1.325449
78.19798	-1.328236
78.67237	-1.331729
79.15537	-1.335276
79.62879	-1.339068
80.10339	-1.343715
80.58588	-1.348426
81.0684	-1.353291
81.53448	-1.359359
82.01649	-1.36563
82.4989	-1.373486
82.97312	-1.382876
83.44803	-1.396292
83.92986	-1.415614
84.41005	-1.496944
84.87391	-1.525197
85.35788	-1.5312
85.84447	-1.450713
86.32121	-1.388339
86.79711	-1.379614
87.28116	-1.37147
87.75531	-1.364254
88.22949	-1.358124
88.71225	-1.353499
89.19468	-1.349762
89.66932	-1.347533
90.14434	-1.345772
90.62762	-1.343843
91.10207	-1.342488
91.57587	-1.340569
92.05932	-1.340296
92.54188	-1.340609
93.00976	-1.340978
93.49266	-1.340248
93.9745	-1.338865
94.44853	-1.338507
94.92298	-1.339261
95.40559	-1.33884
95.88886	-1.339044
96.35416	-1.338704
96.83812	-1.338719
97.32282	-1.341364
97.79765	-1.341508
98.27066	-1.339892
98.75321	-1.339087
99.22768	-1.338763
99.70257	-1.339667
100.1854	-1.339858
100.6668	-1.338925
101.1409	-1.338848
101.6184	-1.342086
102.1014	-1.342483
102.576	-1.342406
103.0489	-1.341242
103.5326	-1.341109
104.0144	-1.341475
104.4792	-1.341243
104.962	-1.341756
105.4476	-1.34581
105.9225	-1.34615
106.3978	-1.347026
106.8798	-1.346513
107.3621	-1.346225
107.8279	-1.346357
108.3098	-1.346569
108.7922	-1.346798
109.2667	-1.347962
109.7419	-1.349121
110.2233	-1.348336
110.6988	-1.349636
111.175	-1.351205
111.6579	-1.351622
112.1408	-1.351954
112.613	-1.350491
113.0899	-1.353312
113.5742	-1.354872
114.0492	-1.355122
114.5217	-1.35389
115.0036	-1.352896
115.4856	-1.353103
115.9516	-1.353561
116.435	-1.354542
116.9177	-1.355758
117.3923	-1.356661
117.868	-1.357381
118.3499	-1.357629
118.8324	-1.357608
119.2294	-1.01266
119.4881	-0.6748268
119.646	-0.4953562
119.7407	-0.3992248
119.7943	-0.3364415
119.8246	-0.3155129
119.8382	-0.2969578
119.8418	-0.2828972
119.8412	-0.2714052
119.8397	-0.265387
119.8371	-0.260716
119.834	-0.2579275
119.8322	-0.257477
119.8302	-0.257251
119.8274	-0.2570528
119.8268	-0.2569115
119.8258	-0.2582777
119.8258	-0.2593345
119.8261	-0.2600271
119.827	-0.2605605
119.8269	-0.2611261
119.8265	-0.2611725
119.8273	-0.260914
119.8277	-0.261136
119.8284	-0.2619479
119.8265	-0.2595484
119.8293	-0.2615478
119.8326	-0.2648946
119.8324	-0.26345
119.8295	-0.2601644
119.83	-0.2608103
119.8031	-0.04144014
119.6226	0.4182535
119.3116	0.6659141
118.9324	0.7804761
118.5121	0.8352624
118.0634	0.8473126
117.6117	0.8568264
117.1516	0.8677269
116.6782	0.8775758
116.2019	0.8852819
115.7392	0.8919386
115.2608	0.895583
114.7816	0.8977966
114.3075	0.9023822
113.8369	0.901716
113.3564	0.9032175
112.8741	0.906507
112.4093	0.9060968
111.9282	0.9068951
111.4455	0.908558
110.9721	0.9081353
110.4981	0.9081324
110.0166	0.9084397
109.5421	0.9088953
109.0685	0.9091326
108.5869	0.9083005
108.1057	0.9083501
107.6315	0.9088459
107.1568	0.9100543
106.6754	0.9095692
106.2013	0.9091612
105.7278	0.9090866
105.2453	0.9097474
104.7623	0.9101128
104.2965	0.9096918
103.8134	0.9101161
103.3321	0.9084629
102.8598	0.9079926
102.3832	0.9109632
101.9008	0.9105701
101.4212	0.9065322
100.9558	0.9077469
100.4723	0.9103332
99.98922	0.913168
99.51545	0.9139496
99.0404	0.9146447
98.55832	0.9157098
98.08316	0.9161651
97.60962	0.9157926
97.12692	0.9160946
96.64449	0.916252
96.17108	0.9163269
95.69545	0.9179955
95.21519	0.9164208
94.74189	0.9162591
94.26726	0.9187712
93.78476	0.9194055
93.30275	0.9201056
92.83644	0.920772
92.35356	0.9216786
91.87106	0.9225835
91.39715	0.9226361
90.9227	0.9238731
90.44012	0.9253028
89.95702	0.92682
89.4918	0.9267445
89.01056	0.9275753
88.52731	0.9300132
88.05418	0.9313004
87.57844	0.9347272
87.09718	0.9364258
86.62406	0.9395892
86.14945	0.9455366
85.66688	0.9606616
85.19091	1.168854
84.71622	1.14816
84.24103	1.14026
83.75653	1.095526
83.28004	1.042603
82.80647	1.022936
82.32332	1.011148
81.84124	0.9995858
81.37437	0.9900312
80.89166	0.9808151
80.40801	0.9732739
79.93408	0.9655297
79.46036	0.9589084
78.97669	0.9542602
78.49454	0.9486066
78.02838	0.9446692
77.54337	0.9420562
77.0626	0.93603
76.58979	0.931382
76.11579	0.928505
75.6326	0.926978
75.15794	0.9249491
74.68269	0.9235165
74.19891	0.9214141
73.7174	0.9178272
73.24272	0.916795
72.76718	0.9154187
72.28644	0.9107541
71.81381	0.9080397
71.33788	0.9084276
70.85534	0.9073053
70.3725	0.9060868
69.90612	0.9049532
69.4238	0.9029812
68.94058	0.9013289
68.46634	0.8998245
67.99191	0.8979044
67.51006	0.8965082
67.02625	0.8963126
66.5614	0.8936281
66.07968	0.8919285
65.59664	0.8911563
65.12198	0.8909418
64.64696	0.8898681
64.16412	0.8888069
63.69016	0.8863791
63.21575	0.8852395
62.7315	0.8855952
62.25036	0.8825226
61.7773	0.8799926
61.3042	0.8785394
60.82008	0.879958
60.34413	0.8796656
59.87135	0.8765022
59.39088	0.8739554
58.90718	0.8746571
58.4391	0.8754738
57.95554	0.8747254
57.47289	0.8728898
56.99878	0.8716842
56.52462	0.8709522
56.04131	0.8713006
55.55844	0.8707665
55.09263	0.869667
54.61126	0.8677088
54.12926	0.8670106
53.65398	0.8673938
53.17974	0.8672574
52.69713	0.8668814
52.2227	0.8662134
51.74821	0.8652268
51.26556	0.8647125
50.78306	0.8639489
50.30801	0.8638434
49.83296	0.8635086
49.35194	0.860778
48.87891	0.8595556
48.40378	0.8602882
47.92047	0.8595031
47.43758	0.857911
46.97206	0.8563172
46.48953	0.8554928
46.00662	0.8550434
45.53156	0.8539276
45.05692	0.8528409
44.57402	0.8519922
44.0909	0.8513649
43.62515	0.8497684
43.14334	0.8483285
42.66034	0.8482695
42.18565	0.8479256
41.71168	0.847678
41.22875	0.8469962
40.75539	0.8456457
40.2807	0.8446555
39.79768	0.8443201
39.31496	0.8431699
38.84101	0.8417489
38.36562	0.8413985
37.8831	0.8399791
37.40847	0.8391441
36.93392	0.8385088
36.45137	0.8374137
35.96832	0.8359319
35.50305	0.8347362
35.01931	0.8342632
34.53736	0.8324535
34.06422	0.830816
33.58835	0.8309924
33.10504	0.8305918
32.6236	0.828535
32.15708	0.8278466
31.67381	0.8273381
31.19158	0.8264169
30.71625	0.825683
30.2427	0.824611
29.7603	0.8241488
29.28556	0.8239371
28.81068	0.8235768
28.32867	0.8222545
27.84582	0.8214008
27.37186	0.8204644
26.89681	0.82029
26.41398	0.8196249
25.93981	0.81839
25.46496	0.817473
24.98303	0.8161588
24.49998	0.815503
24.03379	0.814344
23.5519	0.8134164
23.06886	0.8125806
22.59385	0.8121871
22.11945	0.8110794
21.6361	0.8100562
21.15337	0.808495
20.68801	0.8071098
20.20456	0.8058842
19.72192	0.8048934
19.24737	0.8041289
18.77256	0.802927
18.29017	0.800793
17.81538	0.8002588
17.34113	0.79946
16.85892	0.798256
16.37633	0.7972571
15.90211	0.7963884
15.42636	0.7960381
14.94414	0.794964
14.46959	0.7932592
13.9952	0.7924599
13.51216	0.7912136
13.02952	0.7904156
12.56229	0.7898688
12.08012	0.7879028
11.5982	0.7863852
11.12408	0.7850234
10.64958	0.7843665
10.16635	0.7831411
9.683548	0.7821746
9.217119	0.7820911
8.733936	0.7813054
8.252824	0.7815113
7.778095	0.784125
7.302914	0.7883648
6.820522	0.7922303
6.346748	0.7942945
5.87159	0.7930132
5.388943	0.788644
4.905708	0.7836453
4.430762	0.7783966
3.956057	0.7733275
3.473311	0.7688657
2.998578	0.7643326
2.524548	0.7605954
2.041165	0.7574038
1.558732	0.7545714
1.092603	0.7518062
0.6100811	0.7496094
0.1274539	0.7480988
-0.3465486	0.7457319
-0.8217066	0.7439078
-1.30418	0.7425069
-1.788004	0.7409394
-2.253712	0.7389609
-2.737198	0.7374594
-3.219426	0.735273
-3.694068	0.7340688
-4.16799	0.7323261
-4.650702	0.7308231
-5.126074	0.729949
-5.600618	0.7282638
-6.082604	0.7262507
-6.565368	0.7249372
-7.040528	0.7237392
-7.514245	0.7220094
-7.997592	0.7203026
-8.471589	0.7192779
-8.946621	0.717832
-9.429508	0.7161505
-9.911694	0.7148626
-10.37796	0.7132264
-10.86178	0.7115844
-11.34422	0.709956
-11.81928	0.7088095
-12.29416	0.7078557
-12.7758	0.7059874
-13.25936	0.70383
-13.72533	0.702124
-14.20761	0.7004554
-14.69109	0.6986434
-15.16512	0.6965852
-15.63916	0.6948511
-16.12305	0.6932644
-16.59795	0.6913804
-17.0721	0.688927
-17.55526	0.6865187
-18.03827	0.6835811
-18.51272	0.6808929
-18.98696	0.6780299
-19.47084	0.6750985
-19.94526	0.6714588
-20.41897	0.6669903
-20.90195	0.6623428
-21.3858	0.6575735
-21.85173	0.6523805
-22.3346	0.6462704
-22.81822	0.6401014
-23.29343	0.6335735
-23.76858	0.6260628
-24.25083	0.6177476
-24.7344	0.6100676
-25.20135	0.6021399
-25.68416	0.5928446
-26.1675	0.5840587
-26.64263	0.5751072
-27.11707	0.5661769
-27.59998	0.5565729
-28.07565	0.548172
-28.55127	0.5392699
-29.03366	0.5297351
-29.51684	0.5205404
-29.99115	0.5118137
-30.46675	0.5038336
-30.94984	0.4951275
-31.42459	0.486938
-31.89978	0.479284
-32.38272	0.4708818
-32.86612	0.4628516
-33.33275	0.4553726
-33.81564	0.4481696
-34.29839	0.4408236
-34.77322	0.43382
-35.24772	0.4266761
-35.73129	0.4203325
-36.21424	0.4134747
-36.68068	0.4078784
-37.16453	0.4016661
-37.64796	0.3950269
-38.12195	0.3890126
-38.5958	0.3833536
-39.07465	0.3722826
-39.4346	0.09537799
-39.65384	-0.0591726
-39.79203	-0.1248559
-39.87641	-0.1547168
-39.9262	-0.1689212
-39.95485	-0.179121
-39.97164	-0.187678
-39.97852	-0.1935749
-39.98063	-0.1971614
-39.98068	-0.198787
-39.9799	-0.1990916
-39.978	-0.1988359
-39.97711	-0.198284
-39.97653	-0.1974273
-39.97628	-0.1966146
-39.97559	-0.1962322
-39.97572	-0.1957878
-39.97574	-0.1953889
-39.97552	-0.1950967
-39.97646	-0.1951568
-39.97627	-0.1949105
-39.97687	-0.1951232
-39.97716	-0.1953086
-39.9779	-0.1953411
-39.97787	-0.1957583
-39.97769	-0.1957286
-39.97798	-0.1956592
-39.9787	-0.1956371
-39.97903	-0.1958755
-39.9795	-0.1958263
-39.97915	-0.1848504
-39.92041	-0.3377162
-39.70306	-0.5737852
-39.36812	-0.6978496
-38.96792	-0.7448528
-38.54865	-0.7588472
-38.09717	-0.7691638
-37.6345	-0.7779214
-37.17284	-0.7847847
-36.70794	-0.7907007
-36.23189	-0.7963409
-35.75409	-0.8014969
-35.29207	-0.8068704
-34.81086	-0.8132776
-34.3298	-0.8194438
-33.8566	-0.8249832
-33.3849	-0.8305714
-32.90352	-0.8367887
-32.43146	-0.8430637
-31.95802	-0.8499954
-31.47578	-0.8567524
-30.9936	-0.8640606
-30.51972	-0.8708493
-30.04672	-0.8775343
-29.56498	-0.8842572
-29.09127	-0.8913032
-28.61767	-0.8988281
-28.13626	-0.9061256
-27.65385	-0.9142738
-27.18718	-0.9234488
-26.70386	-0.9328109
-26.22285	-0.9416332
-25.74933	-0.9507012
-25.27633	-0.9607566
-24.7949	-0.9714811
-24.31208	-0.9830997
-23.84652	-0.9947699
-23.36522	-1.00642
-22.88347	-1.018077
-22.40938	-1.03071
-21.93453	-1.043029
-21.45239	-1.054022
-20.97893	-1.063666
-20.50469	-1.072773
-20.02232	-1.080775
-19.53976	-1.086789
-19.06541	-1.09065
-18.59102	-1.093558
-18.10778	-1.094685
-17.6328	-1.094423
-17.15825	-1.093674
-16.67514	-1.092402
-16.19322	-1.090547
-15.72715	-1.089314
-15.24463	-1.087929
-14.76196	-1.087296
-14.28709	-1.087808
-13.81179	-1.088414
-13.32927	-1.088294
-12.84723	-1.088364
-12.3805	-1.089102
-11.89807	-1.089928
-11.4155	-1.090434
-10.94096	-1.091449
-10.46664	-1.093212
-9.982147	-1.095173
-9.50771	-1.096887
-9.033468	-1.098007
-8.551757	-1.098957
-8.068707	-1.100352
-7.594681	-1.101708
-7.119257	-1.103573
-6.636997	-1.105093
-6.162559	-1.106667
-5.687465	-1.108583
-5.205764	-1.109712
-4.723295	-1.110882
-4.2561	-1.112942
-3.773347	-1.115263
-3.290529	-1.116793
-2.816258	-1.117852
-2.3419	-1.119108
-1.8588	-1.120664
-1.375287	-1.121896
-0.9097524	-1.123318
-0.4267514	-1.125208
0.0554112	-1.126378
0.5302258	-1.128496
1.004844	-1.13066
1.487864	-1.131998
1.962656	-1.133488
2.436916	-1.13514
2.919628	-1.13686
3.401567	-1.137729
3.87682	-1.140185
4.351219	-1.142864
4.835194	-1.145214
5.309664	-1.147216
5.783335	-1.148496
6.266024	-1.15058
6.748829	-1.152183
7.214476	-1.15433
7.69735	-1.157014
8.17935	-1.159148
8.653056	-1.162195
9.129202	-1.167115
9.612818	-1.171683
10.09476	-1.176842
10.56005	-1.183172
11.04238	-1.192403
11.52381	-1.202671
11.99831	-1.209592
12.47501	-1.206148
12.95891	-1.197944
13.43372	-1.192728
13.90797	-1.189292
14.39015	-1.18771
14.87392	-1.187188
15.34757	-1.18721
15.8219	-1.187938
16.30524	-1.189369
16.78009	-1.190382
17.25393	-1.191727
17.73638	-1.193188
18.21978	-1.194654
18.68582	-1.196237
19.16802	-1.197431
19.65119	-1.198833
20.12655	-1.200695
20.6018	-1.201729
21.08504	-1.203045
21.5674	-1.204221
22.03304	-1.205068
22.5155	-1.206042
22.99778	-1.207255
23.47122	-1.207948
23.94574	-1.20918
24.42927	-1.211404
24.90528	-1.214837
25.38055	-1.216359
25.86328	-1.217114
26.34578	-1.218022
26.81904	-1.218699
27.29315	-1.220127
27.77634	-1.220828
28.2496	-1.222874
28.72549	-1.225589
29.20881	-1.227321
29.69115	-1.228564
30.15858	-1.230552
30.64136	-1.23176
31.1243	-1.232594
31.5982	-1.233534
32.07266	-1.234679
32.55474	-1.236014
33.03853	-1.238422
33.50464	-1.240049
33.98742	-1.241519
34.47013	-1.24208
34.94462	-1.243396
35.41864	-1.245215
35.90195	-1.246716
36.37604	-1.248821
36.84968	-1.249379
37.334	-1.251784
37.81774	-1.253631
38.29214	-1.254672
38.76626	-1.255768
39.24825	-1.256393
39.723	-1.257708
40.19739	-1.259697
40.6809	-1.261404
41.16324	-1.262368
41.62875	-1.263364
42.11274	-1.265157
42.59466	-1.266634
43.07047	-1.268616
43.5451	-1.270183
44.02694	-1.270684
44.50916	-1.271609
44.97676	-1.274035
45.45944	-1.276097
45.94196	-1.277098
46.41642	-1.278164
46.89031	-1.278944
47.37224	-1.279196
47.84809	-1.280896
48.32486	-1.282033
48.80778	-1.281898
49.2899	-1.281548
49.76361	-1.281614
50.23746	-1.282117
50.7205	-1.282879
51.19465	-1.285059
51.66912	-1.286837
52.15197	-1.288415
52.63524	-1.290623
53.10191	-1.292008
53.5838	-1.292785
54.0666	-1.294263
54.5425	-1.296948
55.01746	-1.298727
55.49968	-1.299039
55.98261	-1.299853
56.4489	-1.301223
56.93046	-1.30224
57.41314	-1.303988
57.88926	-1.307002
58.36348	-1.306795
58.84601	-1.306699
59.32043	-1.306902
59.7951	-1.308301
60.2776	-1.3094
60.76002	-1.310531
61.23474	-1.312056
61.70891	-1.31373
62.19146	-1.315016
62.66645	-1.316733
63.14045	-1.31881
63.6237	-1.320117
64.1074	-1.32174
64.57295	-1.32366
65.05671	-1.325821
65.53995	-1.32719
66.01422	-1.328434
66.48813	-1.329676
66.97116	-1.33104
67.45386	-1.332472
67.91778	-1.333269
68.4009	-1.334994
68.88569	-1.338626
69.36069	-1.341179
69.83575	-1.342945
70.3177	-1.343642
70.79179	-1.34522
71.26668	-1.346607
71.74898	-1.347664
72.23243	-1.349258
72.70611	-1.350301
73.18106	-1.351657
73.6632	-1.353909
74.13728	-1.355644
74.61199	-1.358703
75.0959	-1.361244
75.57806	-1.363508
76.04391	-1.365745
76.52755	-1.368627
77.00961	-1.371038
77.48313	-1.373078
77.95953	-1.378102
78.44308	-1.381926
78.92608	-1.384834
79.3911	-1.387526
79.87332	-1.390672
80.35551	-1.39452
80.82879	-1.398484
81.29998	-1.400856
81.7855	-1.410534
82.26476	-1.420643
82.7403	-1.426208
83.22088	-1.431482
83.7003	-1.438302
84.17278	-1.454021
84.64505	-1.537449
85.12606	-1.583924
85.60131	-1.584029
86.079	-1.493212
86.56476	-1.437035
87.0493	-1.427928
87.51522	-1.418728
87.99835	-1.412102
88.48126	-1.40624
88.95481	-1.400708
89.42994	-1.398353
89.91522	-1.397225
90.39932	-1.395427
90.86601	-1.392474
91.34472	-1.387598
91.8282	-1.387395
92.30769	-1.391544
92.7809	-1.388833
93.26269	-1.386354
93.73569	-1.385198
94.20965	-1.384528
94.69095	-1.38337
95.17364	-1.38284
95.64891	-1.384146
96.12439	-1.385453
96.60884	-1.385798
97.08397	-1.385394
97.55887	-1.385169
98.04062	-1.383993
98.52264	-1.383698
98.98926	-1.384379
99.47182	-1.384083
99.95472	-1.383249
100.4293	-1.383226
100.9041	-1.38343
101.3872	-1.382241
101.8698	-1.380806
102.3356	-1.380247
102.8195	-1.380758
103.3011	-1.380127
103.7721	-1.377426
104.2502	-1.381264
104.74	-1.387592
105.2142	-1.385111
105.685	-1.381261
106.1659	-1.379518
106.6469	-1.379545
107.1188	-1.379258
107.5912	-1.378928
108.0795	-1.385691
108.5608	-1.392164
109.0355	-1.39045
109.5141	-1.384642
109.9957	-1.383132
110.4609	-1.382649
110.9418	-1.382243
111.4249	-1.383769
111.8993	-1.38492
112.3752	-1.38668
112.8594	-1.387941
113.3434	-1.389458
113.8096	-1.389182
114.2926	-1.389078
114.7746	-1.388181
115.249	-1.388753
115.7228	-1.389335
116.2049	-1.389079
116.6799	-1.389976
117.1546	-1.392018
117.6376	-1.392614
118.1212	-1.393523
118.594	-1.392637
119.0534	-1.285794
119.3837	-0.8542316
119.582	-0.611869
119.7026	-0.4745378
119.7738	-0.3974515
119.8121	-0.3596615
119.8334	-0.3449133
119.8425	-0.330957
119.8428	-0.3169626
119.8404	-0.3070671
119.8371	-0.3011739
119.8325	-0.2970149
119.8304	-0.2965393
119.8283	-0.2966223
119.8268	-0.2969265
119.8254	-0.2976041
119.826	-0.2994856
119.8256	-0.2996956
119.8247	-0.2998448
119.8258	-0.3008978
119.8252	-0.3006946
119.8235	-0.2992478
119.8267	-0.3025009
119.8285	-0.304345
119.827	-0.3025534
119.8274	-0.3020101
119.8282	-0.3022169
119.8279	-0.3018197
119.8278	-0.3011941
119.8273	-0.3006829
119.8269	-0.3007169
119.8244	-0.301535
119.727	0.1725246
119.4774	0.5131304
119.1311	0.6889464
118.7222	0.767002
118.2818	0.7970406
117.8428	0.8089124
117.3773	0.8208836
116.9066	0.8315828
116.4393	0.8402918
115.9702	0.846841
115.4925	0.851567
115.021	0.8565069
114.548	0.8608774
114.07	0.8604835
113.5902	0.861127
113.1153	0.8649181
112.6399	0.8686353
112.1633	0.8634256
111.692	0.8626207
111.217	0.8666694
110.7328	0.8704199
110.2492	0.8718692
109.7828	0.8726447
109.3002	0.8724308
108.821	0.8696309
108.347	0.8704093
107.8726	0.8713438
107.3911	0.871575
106.9093	0.8713101
106.4429	0.8728703
105.9613	0.872766
105.4798	0.8724741
105.005	0.8733331
104.5311	0.8735512
104.0484	0.8732593
103.5748	0.8734494
103.101	0.8737039
102.6184	0.8737954
102.1361	0.8752926
101.6602	0.8772901
101.1878	0.8756661
100.7072	0.876067
100.2337	0.8785504
99.75788	0.8815118
99.27562	0.8828755
98.79249	0.8840061
98.3258	0.885845
97.84413	0.8850555
97.36189	0.8850709
96.88768	0.8846559
96.41412	0.8848144
95.93158	0.8849634
95.44831	0.8857897
94.98264	0.8861711
94.50028	0.8864687
94.01786	0.8869155
93.54386	0.8877066
93.07009	0.8882709
92.58758	0.8889924
92.11281	0.8901816
91.63934	0.8903919
91.15697	0.8913575
90.67495	0.8929452
90.20041	0.894673
89.72701	0.8953754
89.24506	0.8963108
88.76947	0.8987647
88.2953	0.9005256
87.8135	0.9013451
87.33188	0.9039047
86.86572	0.9087876
86.38368	0.9149859
85.9016	0.9280691
85.43241	1.133192
84.95744	1.115096
84.47587	1.10037
83.99249	1.059887
83.52506	1.011475
83.04088	0.9982508
82.55785	0.9838993
82.08264	0.9718238
81.60832	0.9608056
81.125	0.9518856
80.65088	0.9431256
80.17642	0.9363954
79.6936	0.9301666
79.21099	0.9251988
78.73611	0.9203282
78.263	0.9156829
77.7792	0.9126118
77.30496	0.9094649
76.83075	0.9051759
76.34975	0.9020186
75.86628	0.9007422
75.39988	0.8985981
74.91748	0.895821
74.4356	0.8935086
73.96011	0.89166
73.48542	0.8905376
73.00234	0.8887174
72.52102	0.8859149
72.05494	0.8837658
71.5731	0.8825624
71.08932	0.8823359
70.61516	0.8804312
70.14026	0.8786506
69.65788	0.8775474
69.18313	0.8770956
68.70844	0.8757047
68.22636	0.8742794
67.74366	0.8728766
67.26846	0.8723929
66.79542	0.8702091
66.31344	0.8685028
65.8386	0.867923
65.3643	0.8674708
64.88132	0.8667772
64.39794	0.865337
63.93145	0.8644599
63.45035	0.8627453
62.96856	0.8615551
62.49391	0.8610576
62.01895	0.8604012
61.53649	0.8592536
61.05261	0.8588012
60.58531	0.8585525
60.1054	0.8547306
59.6225	0.8540568
59.14858	0.8539355
58.6723	0.8548859
58.18986	0.8534282
57.7164	0.8524712
57.24193	0.8519334
56.7592	0.8514666
56.27646	0.8509952
55.80188	0.850291
55.3275	0.8494564
54.84411	0.8491296
54.37	0.8486129
53.8961	0.8476625
53.41291	0.8485337
52.92916	0.8492564
52.46588	0.8462116
51.98526	0.8441876
51.50213	0.845417
51.0263	0.8465184
50.55074	0.846046
50.0679	0.8455439
49.58448	0.8448053
49.11778	0.8441364
48.63586	0.8416653
48.1544	0.8400803
47.6802	0.8398261
47.20583	0.8397324
46.72292	0.8393035
46.24816	0.8388778
45.7726	0.8382516
45.29078	0.8373093
44.80772	0.835991
44.33481	0.8349342
43.86012	0.835067
43.37799	0.8336389
42.90378	0.8322426
42.4285	0.8320382
41.94452	0.8319358
41.46288	0.829902
40.99679	0.8291022
40.514	0.8284595
40.03063	0.8281937
39.55644	0.8274344
39.08155	0.8269776
38.59922	0.8260897
38.11664	0.82573
37.6503	0.8251049
37.16818	0.8241464
36.68592	0.8232246
36.212	0.8229394
35.73742	0.8227837
35.2543	0.8221492
34.77937	0.822471
34.30402	0.8212772
33.82246	0.8191568
33.33978	0.8181921
32.86519	0.8175457
32.39053	0.8168988
31.90723	0.81638
31.43298	0.814878
30.95856	0.8138134
30.47636	0.8119266
29.99422	0.8106274
29.52759	0.810303
29.04457	0.8098926
28.56284	0.8087782
28.08765	0.8085326
27.61259	0.8078366
27.12949	0.8067955
26.6468	0.8056947
26.18137	0.8044406
25.699	0.8029388
25.21715	0.8024795
24.7415	0.8020718
24.26764	0.8005776
23.7846	0.8002489
23.30904	0.7997564
22.8355	0.79738
22.35308	0.795543
21.87085	0.7946572
21.39575	0.7943744
20.92106	0.7933555
20.43798	0.7923899
19.96371	0.7912837
19.48938	0.7893462
19.00535	0.7891352
18.52295	0.7886011
18.05695	0.7874321
17.57501	0.7857595
17.09275	0.7844125
16.61803	0.7835694
16.14245	0.7832997
15.6593	0.7822534
15.17728	0.7798226
14.7127	0.7785214
14.22992	0.7777485
13.74614	0.777304
13.27126	0.7769589
12.79671	0.7767878
12.3135	0.7755432
11.8393	0.774221
11.36462	0.7732603
10.88219	0.7721638
10.39967	0.7710881
9.924816	0.7707628
9.44933	0.77051
8.967508	0.7700999
8.493203	0.7710032
8.018728	0.7727768
7.536743	0.7755158
7.053578	0.77883
6.58878	0.7792626
6.105166	0.7785972
5.622198	0.7757282
5.148006	0.7715711
4.672228	0.7677689
4.189336	0.7630587
3.70596	0.7593024
3.239962	0.7551929
2.75667	0.7511762
2.274535	0.748461
1.799921	0.7450878
1.324882	0.7436371
0.842797	0.7409631
0.3682803	0.7395072
-0.1068374	0.7378616
-0.5892205	0.7357281
-1.071859	0.7340509
-1.547184	0.7324416
-2.021803	0.7308955
-2.504761	0.729114
-2.978039	0.727082
-3.452334	0.7259829
-3.936345	0.7248398
-4.419234	0.7238749
-4.885326	0.7224049
-5.367803	0.720459
-5.850186	0.7189895
-6.32397	0.7176418
-6.79928	0.7168909
-7.282134	0.7156184
-7.764942	0.7145507
-8.230894	0.713151
-8.71413	0.711911
-9.196886	0.710946
-9.67095	0.709339
-10.14609	0.7079985
-10.62841	0.7064257
-11.10299	0.7051897
-11.57706	0.7037731
-12.06067	0.7031328
-12.54439	0.7017532
-13.01791	0.6992272
-13.49256	0.6974835
-13.97474	0.6958843
-14.45026	0.6947455
-14.92456	0.6930968
-15.40779	0.691459
-15.89076	0.6895332
-16.35649	0.6874468
-16.84034	0.6849405
-17.32273	0.6827182
-17.79789	0.6801404
-18.27211	0.676605
-18.75557	0.674124
-19.23894	0.6702986
-19.704	0.6650576
-20.18608	0.6607616
-20.66944	0.6562989
-21.14467	0.6516739
-21.62002	0.6462369
-22.10318	0.6400671
-22.57736	0.6330726
-23.05346	0.6258668
-23.53642	0.6188184
-24.02032	0.6108829
-24.49415	0.6021963
-24.96899	0.593115
-25.45242	0.5845574
-25.92716	0.5759284
-26.40278	0.5670264
-26.88572	0.5575884
-27.36822	0.5488426
-27.8352	0.5397898
-28.31815	0.53141
-28.80096	0.5219682
-29.27632	0.513406
-29.75122	0.5053092
-30.2349	0.4973959
-30.71753	0.4883004
-31.1842	0.480578
-31.66682	0.4729461
-32.15045	0.4651194
-32.62533	0.4578976
-33.09945	0.4501656
-33.58391	0.4432164
-34.05798	0.4365665
-34.53381	0.4308372
-35.01648	0.4236616
-35.499	0.4173019
-35.97379	0.4111187
-36.44821	0.4053513
-36.93238	0.3989392
-37.4061	0.3934635
-37.8812	0.3880686
-37.99808	0.3867